Workbook

Sheet Tracker
A1: Friah's Debt Tracker - YEAR 2026 - mid 2027
B19: 46068 | C19: Amount | D19: Progress | F19: 46081 | G19: Amount | H19: Progress | J19: 46096 | K19: Amount | L19: Progress | N19: 46111 | O19: Amount | P19: Progress | R19: 46127 | S19: Amount | T19: Progress | V19: 46142 | W19: Amount | X19: Progress
B20: Laptop | C20: 1875 | D20: TRUE | F20: Laptop | G20: 1875 | H20: TRUE | J20: Laptop | K20: 1875 | L20: TRUE | N20: Laptop | O20: 1875 | P20: TRUE | R20: Laptop | S20: 1875 | T20: TRUE | V20: Laptop | W20: 1875 | X20: TRUE
B21: iPhone 17 | C21: 2416 | D21: TRUE | F21: iPhone 17 | G21: 2416 | H21: TRUE | J21: iPhone 17 | K21: 2416 | L21: TRUE | N21: iPhone 17 | O21: 2416 | P21: TRUE | R21: iPhone 17 | S21: 2416 | T21: TRUE | V21: iPhone 17 | W21: 2416 | X21: TRUE
B22: Xiaomi 15t | C22: 1208 | D22: TRUE | F22: Xiaomi 15t | G22: 1208 | H22: TRUE | J22: Xiaomi 15t | K22: 1208 | L22: TRUE | N22: Xiaomi 15t | O22: 1208 | P22: TRUE | R22: Xiaomi 15t | S22: 1208 | T22: TRUE | V22: Xiaomi 15t | W22: 1208 | X22: TRUE
B23: Skyro | C23: 995 | D23: TRUE | F23: Wifi | G23: 749 | H23: TRUE | J23: FT Lending | K23: 1493 | L23: TRUE | N23: Wifi | O23: 749 | P23: TRUE | R23: iPhone 16 | S23: 3791 | T23: TRUE | V23: iPhone 16 | W23: 1896 | X23: TRUE
B24: Billease ni mama | C24: 882 | D24: TRUE | F24: Gloan | G24: 309 | H24: TRUE | J24: Gloan | K24: 986 | L24: TRUE | N24: Gloan | O24: 309 | P24: TRUE | R24: Gloan | S24: 986 | T24: TRUE | V24: Wifi | W24: 749 | X24: TRUE
B25: FT Lending | C25: 1182 | D25: TRUE | F25: Tala | G25: 2909 | H25: TRUE | J25: Ggives | K25: 747 | L25: TRUE | N25: UnoB Loan | O25: 2874 | P25: TRUE | R25: Ggives | S25: 747 | T25: TRUE | V25: Gloan | W25: 309 | X25: TRUE
B26: Gloan | C26: 986 | D26: TRUE | F26: UnoB Loan | G26: 2874 | H26: TRUE | J26: Ggives 2 | K26: 475 | L26: TRUE | N26: Sloan | O26: 590 | P26: TRUE | R26: Ggives 2 | S26: 475 | T26: TRUE | V26: UnoB Loan | W26: 2874 | X26: TRUE
B27: Ggives | C27: 747 | D27: TRUE | F27: Sloan | G27: 590 | H27: TRUE | J27: Billease ni lovey | K27: 1024 | L27: TRUE | N27: FT Lending | O27: 1346 | P27: TRUE | R27: Spaylater | S27: 937 | T27: TRUE | V27: Sloan | W27: 590 | X27: TRUE
B28: Ggives 2 | C28: 475 | D28: TRUE | F28: FT Lending | G28: 834 | H28: TRUE | J28: Billease ni lovey | K28: 213 | L28: TRUE | N28: Billease ni lovey | O28: 1024 | P28: TRUE | R28: Tiktok Pay | S28: 916 | T28: TRUE | V28: Braces adj | W28: 1000 | X28: TRUE
B29: Billease ni lovey | C29: 1024 | D29: TRUE | F29: Billease ni lovey | G29: 1024 | H29: TRUE | J29: Spaylater | K29: 801 | L29: TRUE | N29: Billease ni lovey | O29: 213 | P29: TRUE | R29: Tiktok Loan | S29: 517 | T29: TRUE | V29: Billease | W29: 673 | X29: TRUE
B30: Billease ni lovey | C30: 213 | D30: TRUE | F30: Billease ni lovey | G30: 213 | H30: TRUE | J30: Tiktok Pay | K30: 1590 | L30: TRUE | N30: Billease | O30: 673 | P30: TRUE | R30: Billease | S30: 673 | T30: TRUE | V30: Maribank | W30: 565 | X30: TRUE
B31: Spaylater | C31: 1200 | D31: TRUE | F31: Billease | G31: 1345 | H31: TRUE | J31: Tiktok Loan | K31: 517 | L31: TRUE | N31: Braces Adj | O31: 1000 | P31: TRUE | R31: Maribank | S31: 565 | T31: TRUE | V31: Skyro | W31: 5530 | X31: TRUE
B32: TiktokPay | C32: 916 | D32: TRUE | F32: Braces Adj | G32: 1000 | H32: TRUE | J32: Billease | K32: 673 | L32: TRUE | N32: Maribank | O32: 565 | P32: TRUE | R32: Maribank | S32: 1129 | T32: TRUE | V32: Maribank | W32: 1129 | X32: TRUE
B33: TiktokLoan | C33: 517 | D33: TRUE | J33: Maribank | K33: 1129 | L33: TRUE | N33: Maribank | O33: 2256 | P33: TRUE
B35: Remaining Balance | C35: =SUMIF(D20:D33, FALSE, C20:C33) -> 0 | D35: =IF(C35=0, "PAID", "UNPAID") -> PAID | F35: Remaining Balance | G35: =SUMIF(H20:H32, FALSE,G20:G32) -> 0 | H35: =IF(G35=0, "PAID", "UNPAID") -> PAID | J35: Remaining Balance | K35: =SUMIF(L20:L33, FALSE, K20:K33) -> 0 | L35: =IF(K35=0, "PAID", "UNPAID") -> PAID | N35: Remaining Balance | O35: =SUMIF(P20:P33, FALSE, O20:O33) -> 0 | P35: =IF(O35=0, "PAID", "UNPAID") -> PAID | R35: Remaining Balance | S35: =SUMIF(T20:T32, FALSE, S20:S32) -> 0 | T35: =IF(S35=0, "PAID", "UNPAID") -> PAID | V35: Remaining Balance | W35: =SUMIF(X20:X32, FALSE, W20:W32) -> 0 | X35: =IF(W35=0, "PAID", "UNPAID") -> PAID
B36: Total Payment | C36: =SUMIF(D20:D33,TRUE,C20:C33) -> 14636 | F36: Total Payment | G36: =SUMIF(H20:H32,TRUE,G20:G32) -> 17346 | J36: Total Payment | K36: =SUMIF(L20:L33,TRUE,K20:K33) -> 15147 | N36: Total Payment | O36: =SUMIF(P20:P33,TRUE,O20:O33) -> 17098 | R36: Total Payment | S36: =SUMIF(T20:T32,TRUE,S20:S32) -> 16235 | V36: Total Payment | W36: =SUMIF(X20:X32,TRUE,W20:W32) -> 20814
B37: Total Balance | C37: =SUM(C20:C33) -> 14636 | F37: Total Balance | G37: =SUM(G20:G32) -> 17346 | J37: Total Balance | K37: =SUM(K20:K33) -> 15147 | N37: Total Balance | O37: =SUM(O20:O33) -> 17098 | R37: Total Balance | S37: =SUM(S20:S32) -> 16235 | V37: Total Balance | W37: =SUM(W20:W32) -> 20814
B39: 46157 | C39: Amount | D39: Progress | F39: 46172 | G39: Amount | H39: Progress | J39: 46188 | K39: Amount | L39: Progress | N39: 46203 | O39: Amount | P39: Progress | R39: 46218 | S39: Amount | T39: Progress | V39: 46233 | W39: Amount | X39: Progress
B40: Laptop | C40: 1875 | D40: TRUE | F40: Laptop | G40: 1875 | H40: FALSE | J40: Laptop | K40: 1875 | L40: FALSE | N40: Laptop | O40: 1875 | P40: FALSE | R40: Laptop | S40: 1875 | T40: FALSE | V40: Laptop | W40: 1875 | X40: FALSE
B41: iPhone 17 | C41: 2416 | D41: TRUE | F41: iPhone 17 | G41: 2416 | H41: FALSE | J41: iPhone 17 | K41: 2416 | L41: FALSE | N41: iPhone 17 | O41: 2416 | P41: FALSE | R41: iPhone 17 | S41: 2416 | T41: FALSE | V41: iPhone 17 | W41: 2416 | X41: FALSE
B42: Xiaomi 15t | C42: 1208 | D42: TRUE | F42: Xiaomi 15t | G42: 1208 | H42: FALSE | J42: Xiaomi 15t | K42: 1208 | L42: FALSE | N42: Xiaomi 15t | O42: 1208 | P42: FALSE | R42: Xiaomi 15t | S42: 1208 | T42: FALSE | V42: Xiaomi 15t | W42: 1208 | X42: FALSE
B43: iPhone 16 | C43: 3791 | D43: TRUE | F43: iPhone 16 | G43: 1896 | H43: FALSE | J43: iPhone 16 | K43: 1896 | L43: FALSE | N43: iPhone 16 | O43: 1896 | P43: FALSE | R43: iPhone 16 | S43: 1896 | T43: FALSE | V43: iPhone 16 | W43: 1896 | X43: FALSE
B44: Gloan | C44: 986 | D44: TRUE | F44: Wifi | G44: 749 | H44: FALSE | J44: Gloan | K44: 986 | L44: FALSE | N44: Wifi | O44: 749 | P44: FALSE | R44: Gloan | S44: 986 | T44: FALSE | V44: Wifi | W44: 749 | X44: FALSE
B45: Ggives | C45: 747 | D45: TRUE | F45: Gloan | G45: 309 | H45: FALSE | J45: Ggives | K45: 747 | L45: FALSE | N45: Gloan | O45: 309 | P45: FALSE | R45: Ggives | S45: 747 | T45: FALSE | V45: UnoB Loan | W45: 2874 | X45: FALSE
B46: Tiktok Loan | C46: 517 | D46: TRUE | F46: UnoB Loan | G46: 2874 | H46: FALSE | J46: Tiktok Loan | K46: 517 | L46: FALSE | N46: UnoB Loan | O46: 2874 | P46: FALSE | R46: Tiktok Loan | S46: 517 | T46: FALSE | V46: Braces adj | W46: 1000 | X46: FALSE
B47: Billease | C47: 673 | D47: TRUE | F47: Sloan | G47: 590 | H47: FALSE | J47: Billease | K47: 673 | L47: FALSE | N47: Braces adj | O47: 1000 | P47: FALSE | R47: Billease | S47: 673 | T47: FALSE | V47: Billease | W47: 673 | X47: FALSE
B48: Maribank | C48: 565 | D48: TRUE | F48: Braces adj | G48: 1000 | H48: FALSE | J48: Maribank | K48: 565 | L48: FALSE | N48: Billease | O48: 673 | P48: FALSE | R48: Maribank | S48: 565 | T48: FALSE | V48: Maribank | W48: 565 | X48: FALSE
B49: Maribank | C49: 1129 | D49: TRUE | F49: Billease | G49: 673 | H49: FALSE | J49: Maribank | K49: 1129 | L49: FALSE | N49: Maribank | O49: 565 | P49: FALSE | R49: Maribank | S49: 1129 | T49: FALSE | V49: Maribank | W49: 1129 | X49: FALSE
F50: Maribank | G50: 565 | H50: FALSE | N50: Maribank | O50: 1129 | P50: FALSE
F51: Maribank | G51: 1129 | H51: FALSE
B55: Remaining Balance | C55: =SUMIF(D40:D49, FALSE, C40:C49) -> 0 | D55: =IF(C55=0, "PAID", "UNPAID") -> PAID | F55: Remaining Balance | G55: =SUMIF(H40:H51, FALSE, G40:G51) -> 15284 | H55: =IF(G55=0, "PAID", "UNPAID") -> UNPAID | J55: Remaining Balance | K55: =SUMIF(L40:L49, FALSE, K40:K49) -> 12012 | L55: =IF(K55=0, "PAID", "UNPAID") -> UNPAID | N55: Remaining Balance | O55: =SUMIF(P40:P50, FALSE, O40:O50) -> 14694 | P55: =IF(O55=0, "PAID", "UNPAID") -> UNPAID | R55: Remaining Balance | S55: =SUMIF(T40:T49, FALSE, S40:S49) -> 12012 | T55: =IF(S55=0, "PAID", "UNPAID") -> UNPAID | V55: Remaining Balance | W55: =SUMIF(X40:X49, FALSE, W40:W49) -> 14385 | X55: =IF(W55=0, "PAID", "UNPAID") -> UNPAID
B56: Total Payment | C56: =SUMIF(D40:D49,TRUE,C40:C49) -> 13907 | F56: Total Payment | G56: =SUMIF(H40:H51,TRUE,G40:G51) -> 0 | J56: Total Payment | K56: =SUMIF(L40:L49,TRUE,K40:K49) -> 0 | N56: Total Payment | O56: =SUMIF(P40:P50,TRUE,O40:O50) -> 0 | R56: Total Payment | S56: =SUMIF(T40:T49,TRUE,S40:S49) -> 0 | V56: Total Payment | W56: =SUMIF(X40:X49,TRUE,W40:W49) -> 0
B57: Total Balance | C57: =SUM(C40:C49) -> 13907 | F57: Total Balance | G57: =SUM(G40:G51) -> 15284 | J57: Total Balance | K57: =SUM(K40:K49) -> 12012 | N57: Total Balance | O57: =SUM(O40:O50) -> 14694 | R57: Total Balance | S57: =SUM(S40:S49) -> 12012 | V57: Total Balance | W57: =SUM(W40:W49) -> 14385
B59: 46249 | C59: Amount | D59: Progress | F59: 46264 | G59: Amount | H59: Progress | J59: 46280 | K59: Amount | L59: Progress | N59: 46295 | O59: Amount | P59: Progress | R59: 46310 | S59: Amount | T59: Progress | V59: 46325 | W59: Amount | X59: Progress
B60: Laptop | C60: 1875 | D60: FALSE | F60: Wifi | G60: 749 | H60: FALSE | J60: iPhone 17 | K60: 2416 | L60: FALSE | N60: iPhone 17 | O60: 2416 | P60: FALSE | R60: iPhone 17 | S60: 2416 | T60: FALSE | V60: iPhone 17 | W60: 2416 | X60: FALSE
B61: iPhone 17 | C61: 2416 | D61: FALSE | F61: iPhone 17 | G61: 2416 | H61: FALSE | J61: Xiaomi 15t | K61: 1208 | L61: FALSE | N61: Xiaomi 15t | O61: 1208 | P61: FALSE | R61: Xiaomi 15t | S61: 1208 | T61: FALSE | V61: Xiaomi 15t | W61: 1208 | X61: FALSE
B62: Xiaomi 15t | C62: 1208 | D62: FALSE | F62: Xiaomi 15t | G62: 1208 | H62: FALSE | J62: Gloan | K62: 986 | L62: FALSE | N62: Wifi | O62: 749 | P62: FALSE | R62: Gloan | S62: 986 | T62: FALSE | V62: Wifi | W62: 749 | X62: FALSE
B63: iPhone 16 | C63: 1896 | D63: FALSE | F63: Maribank | G63: 565 | H63: FALSE | J63: Maribank | K63: 565 | L63: FALSE | N63: Braces adj | O63: 1000 | P63: FALSE | R63: Maribank | S63: 565 | T63: FALSE | V63: Braces adj | W63: 1000 | X63: FALSE
...

Sheet Summary of payments
B5: Month/Date | C5: Total Monthly Debt | D5: Monthly Income | E5: DTI Ratio | F5: Goal
B6: 46068 | C6: =Tracker!C37 -> 14636 | D6: 12000 | E6: =IFERROR(C6 / $D$7, 0) -> 1.2196667 | F6: 0.36
B7: 46081 | C7: =Tracker!G37 -> 17346 | D7: 12000 | E7: =IFERROR(C7 / $D$7, 0) -> 1.4455 | F7: 0.36
B8: 46096 | C8: =Tracker!K37 -> 15147 | D8: 12000 | E8: =IFERROR(C8 / $D$7, 0) -> 1.26225 | F8: 0.36
B9: 46111 | C9: =Tracker!O37 -> 17098 | D9: 12000 | E9: =IFERROR(C9 / $D$7, 0) -> 1.4248333 | F9: 0.36
B10: 46127 | C10: =Tracker!S37 -> 16235 | D10: 12000 | E10: =IFERROR(C10 / $D$7, 0) -> 1.3529167 | F10: 0.36
B11: 46142 | C11: =Tracker!W37 -> 20814 | D11: 12000 | E11: =IFERROR(C11 / $D$7, 0) -> 1.7345 | F11: 0.36
B12: 46157 | C12: =Tracker!C57 -> 13907 | D12: 12000 | E12: =IFERROR(C12 / $D$7, 0) -> 1.1589167 | F12: 0.36
B13: 46172 | C13: =Tracker!G57 -> 15284 | D13: 12000 | E13: =IFERROR(C13 / $D$7, 0) -> 1.2736667 | F13: 0.36
B14: 46188 | C14: =Tracker!K57 -> 12012 | D14: 12000 | E14: =IFERROR(C14 / $D$7, 0) -> 1.001 | F14: 0.36
B15: 46203 | C15: =Tracker!O57 -> 14694 | D15: 12000 | E15: =IFERROR(C15 / $D$7, 0) -> 1.2245 | F15: 0.36
B16: 46218 | C16: =Tracker!S57 -> 12012 | D16: 12000 | E16: =IFERROR(C16 / $D$7, 0) -> 1.001 | F16: 0.36
B17: 46233 | C17: =Tracker!W57 -> 14385 | D17: 12000 | E17: =IFERROR(C17 / $D$7, 0) -> 1.19875 | F17: 0.36
B18: 46249 | C18: =Tracker!C77 -> 10075 | D18: 12000 | E18: =IFERROR(C18 / $D$7, 0) -> 0.83958333 | F18: 0.36
B19: 46264 | C19: =Tracker!G77 -> 7067 | D19: 12000 | E19: =IFERROR(C19 / $D$7, 0) -> 0.58891667 | F19: 0.36
B20: 46280 | C20: =Tracker!K77 -> 6304 | D20: 12000 | E20: =IFERROR(C20 / $D$7, 0) -> 0.52533333 | F20: 0.36
B21: 46295 | C21: =Tracker!O77 -> 7067 | D21: 12000 | E21: =IFERROR(C21 / $D$7, 0) -> 0.58891667 | F21: 0.36
B22: 46310 | C22: =Tracker!S77 -> 6304 | D22: 12000 | E22: =IFERROR(C22 / $D$7, 0) -> 0.52533333 | F22: 0.36
B23: 46325 | C23: =Tracker!W77 -> 7067 | D23: 12000 | E23: =IFERROR(C23 / $D$7, 0) -> 0.58891667 | F23: 0.36
B24: 46341 | C24: =Tracker!C97 -> 6304 | D24: 12000 | E24: =IFERROR(C24 / $D$7, 0) -> 0.52533333 | F24: 0.36
B25: 46356 | C25: =Tracker!G97 -> 7067 | D25: 12000 | E25: =IFERROR(C25 / $D$7, 0) -> 0.58891667 | F25: 0.36
B26: 46371 | C26: =Tracker!K97 -> 4110 | D26: 12000 | E26: =IFERROR(C26 / $D$7, 0) -> 0.3425 | F26: 0.36
B27: 46386 | C27: =Tracker!O97 -> 3443 | D27: 12000 | E27: =IFERROR(C27 / $D$7, 0) -> 0.28691667 | F27: 0.36
B28: 46402 | C28: =Tracker!S97 -> 1694 | D28: 12000 | E28: =IFERROR(C28 / $D$7, 0) -> 0.14116667 | F28: 0.36
B29: 46417 | C29: =Tracker!W97 -> 3443 | D29: 12000 | E29: =IFERROR(C29 / $D$7, 0) -> 0.28691667 | F29: 0.36
B30: 46433 | C30: =Tracker!C117 -> 1694 | D30: 12000 | E30: =IFERROR(C30 / $D$7, 0) -> 0.14116667 | F30: 0.36
B31: 46446 | C31: =Tracker!G117 -> 3443 | D31: 12000 | E31: =IFERROR(C31 / $D$7, 0) -> 0.28691667 | F31: 0.36
B32: 45731 | C32: =Tracker!K117 -> 1694 | D32: 12000 | E32: =IFERROR(C32 / $D$7, 0) -> 0.14116667 | F32: 0.36
B33: 46476 | C33: =Tracker!O117 -> 1749 | D33: 12000 | E33: =IFERROR(C33 / $D$7, 0) -> 0.14575 | F33: 0.36

Sheet Sheet1
B2: Date | C2: Remaining Debt | F2: Month | G2: Paid
B3: 46068 | C3: =Tracker!$C$35 -> 0 | F3: 46068 | G3: =Tracker!$C$36 -> 14636
B4: 46081 | C4: =Tracker!G35 -> 0 | F4: 46081 | G4: =Tracker!$G$36 -> 17346
B5: 46096 | C5: =Tracker!K35 -> 0 | F5: 46096 | G5: =Tracker!$K$36 -> 15147
B6: 46111 | C6: =Tracker!O35 -> 0 | F6: 46111 | G6: =Tracker!$O$36 -> 17098
B7: 46127 | C7: =Tracker!S35 -> 0 | F7: 46127 | G7: =Tracker!$S$36 -> 16235
B8: 46142 | C8: =Tracker!W35 -> 0 | F8: 46142 | G8: =Tracker!$W$36 -> 20814
B9: 46157 | C9: =Tracker!C55 -> 0 | F9: 46157 | G9: =Tracker!$C$56 -> 13907
B10: 46172 | C10: =Tracker!G55 -> 15284 | F10: 46172 | G10: =Tracker!$G$56 -> 0
B11: 46188 | C11: =Tracker!K55 -> 12012 | F11: 46188 | G11: =Tracker!$K$56 -> 0
B12: 46203 | C12: =Tracker!O55 -> 14694 | F12: 46203 | G12: =Tracker!$O$56 -> 0
B13: 46218 | C13: =Tracker!S55 -> 12012 | F13: 46218 | G13: =Tracker!$S$56 -> 0
B14: 46233 | C14: =Tracker!W55 -> 14385 | F14: 46233 | G14: =Tracker!$W$56 -> 0
B15: 46249 | C15: =Tracker!C75 -> 10075 | F15: 46249 | G15: =Tracker!C76 -> 0
B16: 46264 | C16: =Tracker!G75 -> 7067 | F16: 46264 | G16: =Tracker!G76 -> 0
B17: 46280 | C17: =Tracker!K75 -> 6304 | F17: 46280 | G17: =Tracker!K76 -> 0
B18: 46295 | C18: =Tracker!O75 -> 7067 | F18: 46295 | G18: =Tracker!O76 -> 0
B19: 46310 | C19: =Tracker!S75 -> 6304 | F19: 46310 | G19: =Tracker!S76 -> 0
B20: 46325 | C20: =Tracker!W75 -> 7067 | F20: 46325 | G20: =Tracker!W76 -> 0
B21: 46341 | C21: =Tracker!C95 -> 6304 | F21: 46341 | G21: =Tracker!C96 -> 0
B22: 46356 | C22: =Tracker!G95 -> 7067 | F22: 46356 | G22: =Tracker!G96 -> 0
B23: 46371 | C23: =Tracker!K95 -> 4110 | F23: 46371 | G23: =Tracker!K96 -> 0
B24: 46386 | C24: =Tracker!O95 -> 3443 | F24: 46386 | G24: =Tracker!O96 -> 0
B25: 46402 | C25: =Tracker!S95 -> 1694 | F25: 46402 | G25: =Tracker!S96 -> 0
B26: 46417 | C26: =Tracker!W95 -> 3443 | F26: 46417 | G26: =Tracker!W96 -> 0
B27: 46433 | C27: =Tracker!C115 -> 1694 | F27: 46433 | G27: =Tracker!C116 -> 0
B28: 46446 | C28: =Tracker!G115 -> 3443 | F28: 46446 | G28: =Tracker!G116 -> 0
B29: 46461 | C29: =Tracker!K115 -> 1694 | F29: 46461 | G29: =Tracker!K116 -> 0
B30: 46476 | C30: =Tracker!O115 -> 1749 | F30: 46476 | G30: =Tracker!O116 -> 0
